Loading nccl/2.23.4-cuda12.6
  Loading requirement: cuda/12.6
Traceback (most recent call last):
  File "/home/gridsan/brich/subgraphrag/BenSubgraphRag/SubGraphRag/retrieve/emb.py", line 123, in <module>
    main(args)
  File "/home/gridsan/brich/subgraphrag/BenSubgraphRag/SubGraphRag/retrieve/emb.py", line 69, in main
    train_set = get_dataset(input_file, 'train')
  File "/home/gridsan/brich/subgraphrag/BenSubgraphRag/SubGraphRag/retrieve/emb.py", line 36, in get_dataset
    dataset = load_dataset(input_file, split=split)
  File "/home/gridsan/brich/.conda/envs/gte_large_en_v1-5/lib/python3.10/site-packages/datasets/load.py", line 2594, in load_dataset
    builder_instance = load_dataset_builder(
  File "/home/gridsan/brich/.conda/envs/gte_large_en_v1-5/lib/python3.10/site-packages/datasets/load.py", line 2266, in load_dataset_builder
    dataset_module = dataset_module_factory(
  File "/home/gridsan/brich/.conda/envs/gte_large_en_v1-5/lib/python3.10/site-packages/datasets/load.py", line 1914, in dataset_module_factory
    raise e1 from None
  File "/home/gridsan/brich/.conda/envs/gte_large_en_v1-5/lib/python3.10/site-packages/datasets/load.py", line 1845, in dataset_module_factory
    raise ConnectionError(f"Couldn't reach '{path}' on the Hub ({e.__class__.__name__})") from e
ConnectionError: Couldn't reach 'rmanluo/RoG-cwq' on the Hub (ConnectionError)
